# Uri-challenge-python
Some Uri problem solved with Python 3.7 :)
